Workbook
Name colArea: _xlfn.ANCHORARRAY(Filter_Lists!$E$2)
Name colBody: _xlfn.ANCHORARRAY(Filter_Lists!$H$2)
Name colDept: _xlfn.ANCHORARRAY(Filter_Lists!$D$2)
Name colDOI: _xlfn.ANCHORARRAY(Filter_Lists!$B$2)
Name colESI: _xlfn.ANCHORARRAY(Filter_Lists!$I$2)
Name colJTP: _xlfn.ANCHORARRAY(Filter_Lists!$F$2)
Name colMonth: _xlfn.ANCHORARRAY(Filter_Lists!$L$2)
Name colName: _xlfn.ANCHORARRAY(Filter_Lists!$A$2)
Name colRec: _xlfn.ANCHORARRAY(Filter_Lists!$J$2)
Name colSup: _xlfn.ANCHORARRAY(Filter_Lists!$C$2)
Name colType: _xlfn.ANCHORARRAY(Filter_Lists!$G$2)
Name colYear: _xlfn.ANCHORARRAY(Filter_Lists!$K$2)
Name fMask: _xlfn.ANCHORARRAY(Filter_Lists!$X$2)
Name fromOffset: Filter_Lists!$V$3
Name listArea: _xlfn.ANCHORARRAY(Filter_Lists!$T$2)
Name listDept: _xlfn.ANCHORARRAY(Filter_Lists!$N$2)
Name listESI: _xlfn.ANCHORARRAY(Filter_Lists!$Q$2)
Name listRec: _xlfn.ANCHORARRAY(Filter_Lists!$R$2)
Name listSup: _xlfn.ANCHORARRAY(Filter_Lists!$O$2)
Name listType: _xlfn.ANCHORARRAY(Filter_Lists!$P$2)
Name listYear: _xlfn.ANCHORARRAY(Filter_Lists!$S$2)
Name maxDOI: Filter_Lists!$V$2
Name minDOI: Filter_Lists!$V$1
Name selArea: 'Filter Dashboard'!$C$6
Name selDept: 'Filter Dashboard'!$C$5
Name selESI: 'Filter Dashboard'!$F$5
Name selFrom: 'Filter Dashboard'!$I$5
Name selMode: 'Filter Dashboard'!$I$7
Name selRec: 'Filter Dashboard'!$F$6
Name selSearch: 'Filter Dashboard'!$F$8
Name selSup: 'Filter Dashboard'!$C$7
Name selTo: 'Filter Dashboard'!$I$6
Name selType: 'Filter Dashboard'!$C$8
Name selYear: 'Filter Dashboard'!$F$7
Name Slicer_Area: #N/A
Name Slicer_Department: #N/A
Name Slicer_ESI_Status: #N/A
Name Slicer_JTP: #N/A
Name Slicer_Month: #N/A
Name Slicer_Month1: #N/A
Name Slicer_Supervisor: #N/A
Name Slicer_Year: #N/A
Name Slicer_Year1: #N/A
Name toOffset: Filter_Lists!$V$4

Sheet Filter Dashboard
A1: INCIDENTS RECORDS — FILTER DASHBOARD
A2: ="Showing "&TEXT(SUM(fMask),"#,##0")&" of "&TEXT(ROWS(colDOI),"#,##0")&" records ("&TEXT(SUM(fMask)/ROWS(colDOI),"0.0%")&" of total) • Mode: "&selMode -> Showing 275 of 580 records (47.4% of total) • Mode: AND
B4: FILTERS | N4: SETUP (one-time, ~2 min)
B5: Department | C5: (All) | E5: ESI Status | F5: (All) | H5: DOI From | I5: 46023 | N5: 1) SLIDERS: Developer ▸ Insert ▸ Scroll Bar (Form Control). Draw two next to DOI From/To. Right-click ▸ Format Control ▸ Cell link: Filter_Lists!$V$3 (From) and Filter_Lists!$V$4 (To). Min 0, Max 565.
B6: Area | C6: (All) | E6: Recordable | F6: (All) | H6: DOI To | I6: 46387 | N6: 2) CLEAR BUTTON: Added — red "CLEAR ALL FILTERS" button sits right of the filter panel. To make it live: right-click it ▸ Assign Macro ▸ ClearAllFilters (macro code in chat). Until then, ask Claude to reset filters.
B7: Supervisor | C7: (All) | E7: Year | F7: (All) | H7: Match mode | I7: AND | N7: Yellow cells are editable inputs. Area cascades from Department. Set Match mode = OR for any-match logic.
B8: Injury Type | C8: (All) | E8: Search (name/JTP) | H8: (AND / OR)
A10: RECORDS SHOWN | C10: % OF TOTAL | E10: RECORDABLE (Yes) | G10: FIRST AID (FA) | I10: RPO | K10: RECORDABLE (ESI)
A11: =SUM(fMask) -> 275 | C11: =SUM(fMask)/ROWS(colDOI) -> 0.47413793 | E11: {=SUMPRODUCT(fMask,--(colRec="Yes"))} -> 7 | G11: {=SUMPRODUCT(fMask,--(colESI="FA"))} -> 228 | I11: {=SUMPRODUCT(fMask,--(colESI="RPO"))} -> 40 | K11: {=SUMPRODUCT(fMask,--(colESI="RECORDABLE"))} -> 7
A13: FILTERED RESULTS
A15: Name | B15: DOI | C15: Department | D15: Area | E15: Supervisor | F15: JTP | G15: Injury/Illness Type | H15: Body Location | I15: ESI Status | J15: Recordable | K15: Year | L15: Month
A16: {=_xlfn._xlws.FILTER(_xlfn.HSTACK(colName,colDOI,IF(colDept=0,"",colDept),IF(colArea=0,"",colArea),IF(colSup=0,"",colSup),IF(colJTP=0,"",colJTP),IF(colType=0,"",colType),IF(colBody=0,"",colBody),IF(colESI=0,"",colESI),IF(colRec=0,"",colRec),colYear,IF(colMonth=0,"",colMonth)),fMask,"No records match the current filters")} -> Joseph Gomez | B16: 46227 | C16: Harvest | D16: 101 | E16: Richard Xiong | F16: Shackler | G16: Foreign Object | H16: LT - Eye | I16: FA | J16: No | K16: 2026 | L16: July
A17: Ceasar Saldana | B17: 46226 | C17: Maintenance | D17: Maintenance | E17: Jonathan Hernandez | F17: Electrician | G17: Electric Shock | H17: LT - Hand & Forearm | I17: RPO | J17: No | K17: 2026 | L17: July
A18: Irma Ortega | B18: 46225 | C18: Fabrication | D18: 405 | E18: Diego Soria | F18: Whizzard Knife Op. | G18: Strain | H18: RT - Wrist | I18: FA | J18: No | K18: 2026 | L18: July
A19: Noe Frage Ruiz | B19: 46225 | C19: Fabrication | D19: 410 | E19: Juan Ramirez | F19: Chuck Boner | G19: Struck By-Against Object | H19: LT - Thumb | I19: RPO | J19: No | K19: 2026 | L19: July
A20: Ramon Garcia | B20: 46225 | C20: Harvest | D20: 101 | E20: Richard Xiong | F20: 2nd Hock Hang Off | G20: Slip, Trip, & Fall | H20: NA | I20: RPO | J20: No | K20: 2026 | L20: July
A21: Jesus Bernal | B21: 46224 | C21: Corrals | D21: 100 | E21: Marilyn Herrera | F21: Herdsman | G21: Struck By Cattle | H21: RT - Shin/ Calf | I21: FA | J21: No | K21: 2026 | L21: July
A22: Rudy Ramos | B22: 46224 | C22: Harvest | D22: 101 | E22: Richard Xiong | F22: Calf Skinner | G22: Abrasion | H22: RT - Ring Finger | I22: FA | J22: No | K22: 2026 | L22: July
A23: Rosalba Oseguera Mendez | B23: 46223 | C23: Harvest | D23: 102 | E23: Alex Vargas | F23: 2nd Hock Cutter | G23: Strain | H23: RT - Index Finger & Elbow | I23: FA | J23: No | K23: 2026 | L23: July
A24: Christopher Diaz | B24: 46220 | C24: Loading Dock | D24: Loading Dock | E24: Francisco Tapia | F24: Stacker | G24: Strain | H24: RT - Elbow | I24: FA | J24: No | K24: 2026 | L24: July
A25: Eduardo Contreras | B25: 46218 | C25: Harvest | D25: 102 | E25: Alex Vargas | F25: Wax Papper Remover | G25: Rash | H25: LT - Forearm | I25: FA | J25: No | K25: 2026 | L25: July
A26: Carlos Roman | B26: 46217 | C26: Buildings & Grounds | D26: B&G | E26: Christopher Moreno | F26: B&G Maintenace | G26: Struck By-Against Object | H26: RT - Thumb | I26: FA | J26: No | K26: 2026 | L26: July
A27: Maria Figueroa | B27: 46217 | C27: Harvest | D27: 109 | E27: Samuel Sierra | F27: Kidney Pack Off | G27: Burn | H27: RT - Forearm | I27: RPO | J27: No | K27: 2026 | L27: July
A28: Ezequiel Ambriz | B28: 46217 | C28: Utilities | D28: Utilities | E28: Juan Murillo | F28: Utilility - Maintenance | G28: Burn | H28: RT - Forearm | I28: FA | J28: No | K28: 2026 | L28: July
... A290: Sarah Gonzalez | B290: 46029 | C290: Harvest | D290: 101 | E290: Richard Xiong | F290: Whizzard Knife Op. | G290: Strain | H290: LT - Forearm | I290: FA | J290: No | K290: 2026 | L290: January

Sheet Filter_Lists
A1: Name | B1: DOI | C1: Supervisor | D1: Department | E1: Area | F1: JTP | G1: InjuryType | H1: BodyLocation | I1: ESI | J1: Recordable | K1: Year | L1: Month | N1: Dept list | O1: Supervisor list | P1: InjuryType list | Q1: ESI list | R1: Recordable list | S1: Year list | T1: Area list (cascading) | U1: Min DOI | V1: =MIN(colDOI) -> 45660 | X1: Filter mask | AD1: Department | AE1: Filtered Count | AG1: Ref date (data engine) | AH1: =Data!B2 -> 46230
A2: {=Master_List_Of_Injuries[[Employee Name ]]} -> Joseph Gomez | B2: {=Master_List_Of_Injuries[DOI]} -> 46227 | C2: {=Master_List_Of_Injuries[Supervisor]} -> Richard Xiong | D2: {=Master_List_Of_Injuries[[Department ]]} -> Harvest | E2: {=Master_List_Of_Injuries[Area]} -> 101 | F2: {=Master_List_Of_Injuries[JTP:]} -> Shackler | G2: {=Master_List_Of_Injuries[Injury/Illness Type]} -> Foreign Object | H2: {=Master_List_Of_Injuries[Body Location]} -> LT - Eye | I2: {=Master_List_Of_Injuries[ESI Status]} -> FA | J2: {=Master_List_Of_Injuries[Recordable_Flag]} -> No | K2: {=Master_List_Of_Injuries[Year]} -> 2026 | L2: {=Master_List_Of_Injuries[Month]} -> July | N2: {=_xlfn.VSTACK("(All)",_xlfn._xlws.SORT(_xlfn.UNIQUE(_xlfn._xlws.FILTER(colDept,colDept<>""))))} -> (All) | O2: {=_xlfn.VSTACK("(All)",_xlfn._xlws.SORT(_xlfn.UNIQUE(_xlfn._xlws.FILTER(colSup,colSup<>""))))} -> (All) | P2: {=_xlfn.VSTACK("(All)",_xlfn._xlws.SORT(_xlfn.UNIQUE(_xlfn._xlws.FILTER(colType,colType<>""))))} -> (All) | Q2: {=_xlfn.VSTACK("(All)",_xlfn._xlws.SORT(_xlfn.UNIQUE(_xlfn._xlws.FILTER(colESI,colESI<>""))))} -> (All) | R2: {=_xlfn.VSTACK("(All)",_xlfn._xlws.SORT(_xlfn.UNIQUE(_xlfn._xlws.FILTER(colRec,colRec<>""))))} -> (All) | S2: {=_xlfn.VSTACK("(All)",_xlfn._xlws.SORT(_xlfn.UNIQUE(_xlfn._xlws.FILTER(colYear,colYear<>""))))} -> (All) | T2: {=_xlfn.VSTACK("(All)",_xlfn._xlws.SORT(_xlfn.UNIQUE(_xlfn._xlws.FILTER(colArea,(colArea<>"")*IF(selDept="(All)",1,colDept=selDept),"(none)"))))} -> (All) | U2: Max DOI | V2: =MAX(colDOI) -> 46227 | X2: {=_xlfn.LET( _xlpm.acDept,--(selDept<>"(All)"), _xlpm.acArea,--(selArea<>"(All)"), _xlpm.acSup,--(selSup<>"(All)"), _xlpm.acType,--(selType<>"(All)"), _xlpm.acESI,--(selESI<>"(All)"), _xlpm.acRec,--(selRec<>"(All)"), _xlpm.acYear,--(selYear<>"(All)"), _xlpm.mDept,--(colDept=selDept), _xlpm.mArea,--(colArea=selArea), _xlpm.mSup,--(colSup=selSup), _xlpm.mType,--(colType=selType), _xlpm.mESI,--(colESI=selESI), _xlpm.mRec,--(colRec=selRec), _xlpm.mYear,--(colYear=selYear), _xlpm.pAnd,((1-_xlpm.acDept)+_xlpm.acDept*_xlpm.mDept)*((1-_xlpm.acArea)+_xlpm.acArea*_xlpm.mArea)*((1-_xlpm.acSup)+_xlpm.acSup*_xlpm.mSup)*((1-_xlpm.acType)+_xlpm.acType*_xlpm.mType)*((1-_xlpm.acESI)+_xlpm.acESI*_xlpm.mESI)*((1-_xlpm.acRec)+_xlpm.acRec*_xlpm.mRec)*((1-_xlpm.acYear)+_xlpm.acYear*_xlpm.mYear), _xlpm.activeN,_xlpm.acDept+_xlpm.acArea+_xlpm.acSup+_xlpm.acType+_xlpm.acESI+_xlpm.acRec+_xlpm.acYear, _xlpm.orHits,_xlpm.acDept*_xlpm.mDept+_xlpm.acArea*_xlpm.mArea+_xlpm.acSup*_xlpm.mSup+_xlpm.acType*_xlpm.mType+_xlpm.acESI*_xlpm.mESI+_xlpm.acRec*_xlpm.mRec+_xlpm.acYear*_xlpm.mYear, _xlpm.pOr,IF(_xlpm.activeN=0,1,--(_xlpm.orHits>=1)), _xlpm.pCat,IF(selMode="OR",_xlpm.pOr,_xlpm.pAnd), _xlpm.pSearch,IF(selSearch="",1,--(ISNUMBER(SEARCH(selSearch,colName))+ISNUMBER(SEARCH(selSearch,colJTP))>0)), _xlpm.pDate,(colDOI>=selFrom)*(colDOI<=selTo), _xlpm.pCat*_xlpm.pSearch*_xlpm.pDate)} -> 1 | AD2: {=_xlfn._xlws.SORT(_xlfn.UNIQUE(_xlfn._xlws.FILTER(colDept,colDept<>"")))} -> Buildings & Grounds | AE2: {=_xlfn.MAP(_xlfn.ANCHORARRAY(AD2),_xlfn.LAMBDA(_xlpm.d,SUMPRODUCT(fMask,--(colDept=_xlpm.d))))} -> 4
A3: Ceasar Saldana | B3: 46226 | C3: Jonathan Hernandez | D3: Maintenance | E3: Maintenance | F3: Electrician | G3: Electric Shock | H3: LT - Hand & Forearm | I3: RPO | J3: No | K3: 2026 | L3: July | N3: Buildings & Grounds | O3: Alex Vargas | P3: 0 | Q3: FA | R3: No | S3: 2025 | T3: 100 | U3: From offset (slider) | V3: 0 | X3: 1 | AD3: Corrals | AE3: 8 | AG3: Preset | AH3: From | AI3: To
A4: Irma Ortega | B4: 46225 | C4: Diego Soria | D4: Fabrication | E4: 405 | F4: Whizzard Knife Op. | G4: Strain | H4: RT - Wrist | I4: FA | J4: No | K4: 2026 | L4: July | N4: Corrals | O4: Carlos Mata | P4: Above Shoulder Work | Q4: RECORDABLE | R4: Yes | S4: 2026 | T4: 101 | U4: To offset (slider) | V4: 565 | X4: 1 | AD4: Fabrication | AE4: 132 | AG4: (All dates) | AH4: =minDOI -> 45660 | AI4: =maxDOI -> 46227
A5: Noe Frage Ruiz | B5: 46225 | C5: Juan Ramirez | D5: Fabrication | E5: 410 | F5: Chuck Boner | G5: Struck By-Against Object | H5: LT - Thumb | I5: RPO | J5: No | K5: 2026 | L5: July | N5: Fabrication | O5: Chadu Moua | P5: Abrasion | Q5: RPO | T5: 102 | X5: 1 | AD5: FSQA | AE5: 2 | AG5: YTD | AH5: =DATE(YEAR($AH$1),1,1) -> 46023 | AI5: =$AH$1 -> 46230
A6: Ramon Garcia | B6: 46225 | C6: Richard Xiong | D6: Harvest | E6: 101 | F6: 2nd Hock Hang Off | G6: Slip, Trip, & Fall | H6: NA | I6: RPO | J6: No | K6: 2026 | L6: July | N6: FSQA | O6: Christian Lopez | P6: Abrasion | T6: 103 | X6: 1 | AD6: Harvest | AE6: 106 | AG6: Last 7 days | AH6: =$AH$1-6 -> 46224 | AI6: =$AH$1 -> 46230
A7: Jesus Bernal | B7: 46224 | C7: Marilyn Herrera | D7: Corrals | E7: 100 | F7: Herdsman | G7: Struck By Cattle | H7: RT - Shin/ Calf | I7: FA | J7: No | K7: 2026 | L7: July | N7: Harvest | O7: Christopher Moreno | P7: Awkward Posture | T7: 104 | X7: 1 | AD7: Loading Dock | AE7: 3 | AG7: Last 30 days | AH7: =$AH$1-29 -> 46201 | AI7: =$AH$1 -> 46230
A8: Rudy Ramos | B8: 46224 | C8: Richard Xiong | D8: Harvest | E8: 101 | F8: Calf Skinner | G8: Abrasion | H8: RT - Ring Finger | I8: FA | J8: No | K8: 2026 | L8: July | N8: Loading Dock | O8: Clara Salazar | P8: Bending | T8: 105 | X8: 1 | AD8: Maintenance | AE8: 10 | AG8: Last 90 days | AH8: =$AH$1-89 -> 46141 | AI8: =$AH$1 -> 46230
A9: Rosalba Oseguera Mendez | B9: 46223 | C9: Alex Vargas | D9: Harvest | E9: 102 | F9: 2nd Hock Cutter | G9: Strain | H9: RT - Index Finger & Elbow | I9: FA | J9: No | K9: 2026 | L9: July | N9: Maintenance | O9: David Zavala | P9: Box Maker | T9: 106 | X9: 1 | AD9: Maintnances | AE9: 0
A10: Christopher Diaz | B10: 46220 | C10: Francisco Tapia | D10: Loading Dock | E10: Loading Dock | F10: Stacker | G10: Strain | H10: RT - Elbow | I10: FA | J10: No | K10: 2026 | L10: July | N10: Maintnances | O10: Diego Soria | P10: Burn | T10: 107 | X10: 1 | AD10: Outside Clean Up | AE10: 3
A11: Eduardo Contreras | B11: 46218 | C11: Alex Vargas | D11: Harvest | E11: 102 | F11: Wax Papper Remover | G11: Rash | H11: LT - Forearm | I11: FA | J11: No | K11: 2026 | L11: July | N11: Outside Clean Up | O11: Edwin Vega | P11: Burn | T11: 109 | X11: 1 | AD11: Recycling | AE11: 0
A12: Carlos Roman | B12: 46217 | C12: Christopher Moreno | D12: Buildings & Grounds | E12: B&G | F12: B&G Maintenace | G12: Struck By-Against Object | H12: RT - Thumb | I12: FA | J12: No | K12: 2026 | L12: July | N12: Recycling | O12: Elizabeth Neufeld | P12: Contact Stess | T12: 110 | X12: 1 | AD12: Utilities | AE12: 1
A13: Maria Figueroa | B13: 46217 | C13: Samuel Sierra | D13: Harvest | E13: 109 | F13: Kidney Pack Off | G13: Burn | H13: RT - Forearm | I13: RPO | J13: No | K13: 2026 | L13: July | N13: Utilities | O13: Erwin Vega | P13: Contact Stress | T13: 111 | X13: 1 | AD13: Warehouse | AE13: 6
A14: Ezequiel Ambriz | B14: 46217 | C14: Juan Murillo | D14: Utilities | E14: Utilities | F14: Utilility - Maintenance | G14: Burn | H14: RT - Forearm | I14: FA | J14: No | K14: 2026 | L14: July | N14: Warehouse | O14: Francisco Tapia | P14: Contusion | T14: 124 | X14: 1 | AD14: WH | AE14: 0
A15: Jonny Garcia | B15: 46217 | C15: Marilyn Herrera | D15: Corrals | E15: 100 | F15: Herdsman | G15: Struck By Cattle | H15: RT - Calf/ Shin | I15: RPO | J15: No | K15: 2026 | L15: July | N15: WH | O15: Froy Rios | P15: Contusions | T15: 400 | X15: 1
A16: Richie Glass | B16: 46216 | C16: Rene Canas | D16: FSQA | E16: Fab FSQA | F16: QA Tech | G16: Slip, Trip, & Fall | H16: No Injury | I16: RPO | J16: No | K16: 2026 | L16: July | O16: Jarrod Villareal | P16: Crush | T16: 405 | X16: 1
A17: Michael Montelongo | B17: 46213 | C17: Elizabeth Neufeld | D17: Fabrication | E17: 420 | F17: New York Boner | G17: Strain | H17: RT - Wrist | I17: FA | J17: No | K17: 2026 | L17: July | O17: Jesus Avila | P17: Crush Injury | T17: 410 | X17: 1
A18: Rudy Gallegos | B18: 46213 | C18: Samuel Sierra | D18: Harvest | E18: 110 | F18: Cooler Pack Off | G18: Struck by against object | H18: RT - Thumb | I18: FA | J18: No | K18: 2026 | L18: July | O18: Jonathan Hernandez | P18: Crush Injury | T18: 415 | X18: 1
A19: Osbaldo Santiago | B19: 46213 | C19: Alex Vargas | D19: Harvest | E19: 102 | F19: Whizzard Knife Op. | G19: Strain | H19: RT - Ring Finger | I19: RPO | J19: No | K19: 2026 | L19: July | O19: Juan Carlos Martinez | P19: Electric Shock | T19: 420 | X19: 1
A20: Claudia Estrada Cruz | B20: 46212 | C20: Elizabeth Neufeld | D20: Fabrication | E20: 420 | F20: Sorter | G20: Puncture | H20: LT - Palm | I20: FA | J20: No | K20: 2026 | L20: July | O20: Juan Martinez | P20: Falling Object | T20: 429 | X20: 1
A21: Jonathan Campas | B21: 46212 | C21: Samuel Sierra | D21: Harvest | E21: 107 | F21: Cheek Deboner | G21: Foreign Object | H21: RT - Eye | I21: FA | J21: No | K21: 2026 | L21: July | O21: Juan Murillo | P21: Falling Objects | T21: 445 | X21: 1
A22: Daisy Sotelo | B22: 46212 | C22: Samuel Sierra | D22: Harvest | E22: 109 | F22: Offal Floater | G22: Strain | H22: RT - Ring Finger | I22: FA | J22: No | K22: 2026 | L22: July | O22: Juan Ramirez | P22: Foreign boby in eye | T22: 447 | X22: 1
A23: Mason Ojeda | B23: 46212 | C23: Marilyn Herrera | D23: Corrals | E23: 100 | F23: Herdsman | G23: Foreign Object | H23: LT - Eye | I23: RPO | J23: No | K23: 2026 | L23: July | O23: Juan Rodriguez | P23: Foreign Object | T23: B&G | X23: 1
A24: Pisperema Amaya | B24: 46212 | C24: Samuel Sierra | D24: Harvest | E24: 109 | F24: Pack Off | G24: Strain | H24: Lower Back | I24: FA | J24: No | K24: 2026 | L24: July | O24: Kamran Tavagar | P24: Heat Prostration | T24: BG | X24: 1
A25: Hector Razo | B25: 46211 | C25: Christopher Moreno | D25: Buildings & Grounds | E25: B&G | F25: B&G Maintenace | G25: Insect Bite/ Sting | H25: Cranial (Front) | I25: RPO | J25: No | K25: 2026 | L25: July | O25: Manuel Alanis | P25: Impact? | T25: Blood Room | X25: 1
A26: Apolinar Basilio | B26: 46211 | C26: Maria Garcia | D26: Fabrication | E26: 447 | F26: Glue Boxer | G26: Struck by Equipment | H26: RT - Heel | I26: FA | J26: No | K26: 2026 | L26: July | O26: Maria Garcia | P26: Inhalation | T26: Coolers | X26: 1
A27: Mayra Solarte | B27: 46211 | C27: Alex Vargas | D27: Harvest | E27: 102 | F27: Whizzard Knife Operator | G27: Strain | H27: RT - Wrist | I27: RPO | J27: No | K27: 2026 | L27: July | O27: Marilyn Herrera | P27: Inhalation | T27: Corrals 100 | X27: 1
... A41: Raymundo Vargas Jr | B41: 46205 | C41: Erwin Vega | D41: Fabrication | E41: 124 | F41: Cooler Lead | G41: Slip, Trip, & Fall | H41: RT - Hip | I41: RPO | J41: No | K41: 2026 | L41: July | O41: Suky | P41: Reaction | T41: Warehouse | X41: 1
A42: Jose Nunez | B42: 46205 | C42: Erwin Vega | D42: Fabrication | E42: 124 | F42: Cooler Coordinator | G42: Falling Objects | H42: RT - Heel | I42: FA | J42: No | K42: 2026 | L42: July | O42: Valerena Begay | P42: Repetition | X42: 1
A43: Juan Ceballos | B43: 46204 | C43: Michael Orozco | D43: Harvest | E43: 105 | F43: Gutter | G43: Laceration | H43: LT - Hand | I43: RECORDABLE | J43: Yes | K43: 2026 | L43: July | O43: Veronica Figueroa | P43: Slip, Trip, & Fall | X43: 1
A44: Claudia Estrada Cruz | B44: 46204 | C44: Elizabeth Neufeld | D44: Fabrication | E44: 447 | F44: Sorter | G44: Strain | H44: RT - Forearm & Hand & LT - Hand | I44: FA | J44: No | K44: 2026 | L44: July | P44: Sprain | X44: 1
A45: Vilma de Jesus | B45: 46203 | C45: Maria Garcia | D45: Fabrication | E45: 447 | F45: Bone Packer | G45: Contact Stess | H45: LT - Palm | I45: FA | J45: No | K45: 2026 | L45: June | P45: Stike against object | X45: 1
A46: Steven Aceves | B46: 46202 | C46: Ovidio Sanchez | D46: Fabrication | E46: 400 | F46: Scale Operator | G46: Strain | H46: RT - Wrist | I46: FA | J46: No | K46: 2026 | L46: June | P46: Strain | X46: 1
A47: Frederick Garcia | B47: 46202 | C47: Alex Vargas | D47: Harvest | E47: 102 | F47: Bung Capper | G47: Foreign Object | H47: LT - Eye | I47: FA | J47: No | K47: 2026 | L47: June | P47: Strain | X47: 1
A48: Kristy Davila | B48: 46202 | C48: Elizabeth Neufeld | D48: Fabrication | E48: 420 | F48: Flap Meat Trimmer | G48: Foreign Object | H48: LT - Eye | I48: FA | J48: No | K48: 2026 | L48: June | P48: Strike by Cattle | X48: 1
A49: Edgar Guttierez | B49: 46202 | C49: Juan Carlos Martinez | D49: Fabrication | E49: 405 | F49: Plate Boner | G49: Strain | H49: RT - Elbow | I49: FA | J49: No | K49: 2026 | L49: June | P49: Strike-by Against Object | X49: 1
A50: Eduardo Contreras | B50: 46202 | C50: Alex Vargas | D50: Harvest | E50: 102 | F50: Wax Papper Remover | G50: Slip, Trip, & Fall | H50: RT - Knee | I50: RPO | J50: No | K50: 2026 | L50: June | P50: Struck | X50: 1
A51: Aaron Ching | B51: 46202 | C51: Alex Vargas | D51: Harvest | E51: 102 | F51: Clean Up | G51: Strain | H51: RT - Hip | I51: FA | J51: No | K51: 2026 | L51: June | P51: Struck by - against object | X51: 1
A52: Juan Rivera | B52: 46199 | C52: Christopher Moreno | D52: Buildings & Grounds | E52: B&G | F52: Maintenance Lead | G52: Insect Bite/ Sting | H52: Back of Head | I52: RPO | J52: No | K52: 2026 | L52: June | P52: Struck by against object | X52: 1
A53: Osbaldo Santiago | B53: 46199 | C53: Alex Vargas | D53: Harvest | E53: 102 | F53: Whizzard Knife Op. | G53: Burn | H53: LT - Wrist & Hand | I53: FA | J53: No | K53: 2026 | L53: June | P53: Struck By- Against Object | X53: 1
...

Sheet Dashboard
A4: =TEXT(Data!B2,"mmm dd, yyyy")&" · Focus "&Data!B3&" · "&Data!B17&" · Sev "&Data!B96 -> Jul 27, 2026 · Focus 2026 · Medium Risk · Sev 43 | Q4: Focus Yr | R4: =Data!B3 -> 2026
A5: YTD RECORDABLE RATE | C5: DAYS SINCE LAST REC. | O5: SAFETY STATUS
A6: =Data!B11 -> 0.025454545 | C6: =INT(Data!B12) -> 26 | O6: =Data!B17 -> Medium Risk
A9: TOTAL INCIDENTS YTD | C9: RECORDABLE | E9: FIRST AID (FA) | G9: RPO / MOD DUTY | I9: RECORDABLE RATE | K9: DAYS W/O RECORDABLE | M9: LEADING INJURY | O9: TOP DEPARTMENT
A10: =Data!B7 -> 275 | C10: =Data!B8 -> 7 | E10: =Data!B9 -> 228 | G10: =Data!B10 -> 40 | I10: =Data!B11 -> 0.025454545 | K10: =INT(Data!B12) -> 26 | M10: =Data!B13 -> Strain | O10: =Data!B14 -> Fabrication
A12: =Data!B87 -> ▲ +95% vs YTD | C12: =Data!B88 -> ● +0 vs YTD | E12: =Data!B89 -> 83% of YTD | G12: =Data!B90 -> 15% of YTD | I12: =Data!B91 -> ▼ -2.4% | K12: =Data!B92 -> 7/1 · 30+ goal | M12: =Data!B93 -> 97 cases | O12: =Data!B94 -> 48% share
A14: KEY FINDINGS | I14: YTD COMPARISON
A15: =Data!B63&": "&Data!B64&" inc ("&Data!B84&" "&TEXT(Data!B66,"+0;-0")&" MoM)" -> July: 43 inc (▼ -13 MoM) | I15: Metric | J15: 2026 YTD | K15: 2025 YTD | L15: Trend
A16: =Data!B14&" leads ("&TEXT(Data!B67,"0%")&")" -> Fabrication leads (48%) | I16: Total Incidents | J16: =Data!B7 -> 275 | K16: =Data!D7 -> 141 | L16: =Data!B101 -> ▲ +134
A17: =Data!B13&" #1 injury ("&INDEX(_xlfn.ANCHORARRAY(Data!$G$65),1,2)&")" -> Strain #1 injury (97) | I17: Recordable | J17: =Data!B8 -> 7 | K17: =Data!D8 -> 7 | L17: =Data!B102 -> ● 0
A18: ="Rec "&Data!B8&" vs "&Data!D8&" · rate "&TEXT(Data!B11,"0.0%") -> Rec 7 vs 7 · rate 2.5% | I18: First Aid | J18: =Data!B9 -> 228 | K18: =Data!D9 -> 104 | L18: =Data!B103 -> ▲ +124
A19: ="YTD "&Data!B7&" vs "&Data!D7&" ("&TEXT(Data!B68,"+0%;-0%")&")" -> YTD 275 vs 141 (+95%) | I19: RPO | J19: =Data!B10 -> 40 | K19: =Data!D10 -> 30 | L19: =Data!B104 -> ▲ +10
A20: ="ACTION: "&Data!B110 -> ACTION: Focus ergo & coaching in Fabrication; reduce Strain exposures. | I20: Rec. Rate | J20: =Data!B11 -> 0.025454545 | K20: =Data!D11 -> 0.04964539 | L20: =Data!B105 -> ▼ -2.4%
A21: TRENDING
A22: Depts | B22: =INDEX(_xlfn.ANCHORARRAY(Data!$D$65),1,1)&" "&INDEX(_xlfn.ANCHORARRAY(Data!$D$65),1,2) -> Fabrication 132 | C22: =INDEX(_xlfn.ANCHORARRAY(Data!$D$65),2,1)&" "&INDEX(_xlfn.ANCHORARRAY(Data!$D$65),2,2) -> Harvest 106 | D22: =INDEX(_xlfn.ANCHORARRAY(Data!$D$65),3,1)&" "&INDEX(_xlfn.ANCHORARRAY(Data!$D$65),3,2) -> Maintenance 10 | I22: TOP SUPERVISORS
A23: Areas | B23: =INDEX(_xlfn.ANCHORARRAY(Data!$J$65),1,1)&" "&INDEX(_xlfn.ANCHORARRAY(Data!$J$65),1,2) -> 102 32 | C23: =INDEX(_xlfn.ANCHORARRAY(Data!$J$65),2,1)&" "&INDEX(_xlfn.ANCHORARRAY(Data!$J$65),2,2) -> 410 23 | D23: =INDEX(_xlfn.ANCHORARRAY(Data!$J$65),3,1)&" "&INDEX(_xlfn.ANCHORARRAY(Data!$J$65),3,2) -> 420 22 | I23: # | J23: Supervisor | K23: Incidents | L23: Rec.
A24: Supers | B24: =INDEX(_xlfn.ANCHORARRAY(Data!$M$65),1,1)&" "&INDEX(_xlfn.ANCHORARRAY(Data!$M$65),1,2) -> Samuel Sierra 24 | C24: =INDEX(_xlfn.ANCHORARRAY(Data!$M$65),2,1)&" "&INDEX(_xlfn.ANCHORARRAY(Data!$M$65),2,2) -> Elizabeth Neufeld 23 | D24: =INDEX(_xlfn.ANCHORARRAY(Data!$M$65),3,1)&" "&INDEX(_xlfn.ANCHORARRAY(Data!$M$65),3,2) -> Juan Ramirez 21 | I24: 1 | J24: =IFERROR(INDEX(_xlfn.ANCHORARRAY(Data!$M$65),1,1),"") -> Samuel Sierra | K24: =IFERROR(INDEX(_xlfn.ANCHORARRAY(Data!$M$65),1,2),0) -> 24 | L24: =IFERROR(VLOOKUP(J24,Data!$Q$8:$S$17,3,FALSE),0) -> 1
A25: Share | B25: =Data!B107 -> ██████████░░░░░░░░░░ | C25: =TEXT(Data!B67,"0.0%")&" top dept" -> 48.0% top dept | I25: 2 | J25: =IFERROR(INDEX(_xlfn.ANCHORARRAY(Data!$M$65),2,1),"") -> Elizabeth Neufeld | K25: =IFERROR(INDEX(_xlfn.ANCHORARRAY(Data!$M$65),2,2),0) -> 23 | L25: =IFERROR(VLOOKUP(J25,Data!$Q$8:$S$17,3,FALSE),0) -> 0
A26: TOP JTPs | C26: Slicers → PivotCache | I26: 3 | J26: =IFERROR(INDEX(_xlfn.ANCHORARRAY(Data!$M$65),3,1),"") -> Juan Ramirez | K26: =IFERROR(INDEX(_xlfn.ANCHORARRAY(Data!$M$65),3,2),0) -> 21 | L26: =IFERROR(VLOOKUP(J26,Data!$Q$8:$S$17,3,FALSE),0) -> 0
A27: Job | B27: Count | I27: 4 | J27: =IFERROR(INDEX(_xlfn.ANCHORARRAY(Data!$M$65),4,1),"") -> Ovidio Sanchez | K27: =IFERROR(INDEX(_xlfn.ANCHORARRAY(Data!$M$65),4,2),0) -> 21 | L27: =IFERROR(VLOOKUP(J27,Data!$Q$8:$S$17,3,FALSE),0) -> 0
A28: =IFERROR(INDEX(_xlfn.ANCHORARRAY(Data!$P$65),1,1),"") -> Tender Puller | B28: =IFERROR(INDEX(_xlfn.ANCHORARRAY(Data!$P$65),1,2),0) -> 8 | I28: 5 | J28: =IFERROR(INDEX(_xlfn.ANCHORARRAY(Data!$M$65),5,1),"") -> Alex Vargas | K28: =IFERROR(INDEX(_xlfn.ANCHORARRAY(Data!$M$65),5,2),0) -> 19 | L28: =IFERROR(VLOOKUP(J28,Data!$Q$8:$S$17,3,FALSE),0) -> 0
A29: =IFERROR(INDEX(_xlfn.ANCHORARRAY(Data!$P$65),2,1),"") -> Plate Boner | B29: =IFERROR(INDEX(_xlfn.ANCHORARRAY(Data!$P$65),2,2),0) -> 6 | I29: 6 | J29: =IFERROR(INDEX(_xlfn.ANCHORARRAY(Data!$M$65),6,1),"") -> Diego Soria | K29: =IFERROR(INDEX(_xlfn.ANCHORARRAY(Data!$M$65),6,2),0) -> 18 | L29: =IFERROR(VLOOKUP(J29,Data!$Q$8:$S$17,3,FALSE),0) -> 2
A30: =IFERROR(INDEX(_xlfn.ANCHORARRAY(Data!$P$65),3,1),"") -> Intestine Stripper | B30: =IFERROR(INDEX(_xlfn.ANCHORARRAY(Data!$P$65),3,2),0) -> 6 | I30: 7 | J30: =IFERROR(INDEX(_xlfn.ANCHORARRAY(Data!$M$65),7,1),"") -> Christian Lopez | K30: =IFERROR(INDEX(_xlfn.ANCHORARRAY(Data!$M$65),7,2),0) -> 15 | L30: =IFERROR(VLOOKUP(J30,Data!$Q$8:$S$17,3,FALSE),0) -> 0
A31: =IFERROR(INDEX(_xlfn.ANCHORARRAY(Data!$P$65),4,1),"") -> Whizzard Knife Op. | B31: =IFERROR(INDEX(_xlfn.ANCHORARRAY(Data!$P$65),4,2),0) -> 5 | I31: 8 | J31: =IFERROR(INDEX(_xlfn.ANCHORARRAY(Data!$M$65),8,1),"") -> Chadu Moua | K31: =IFERROR(INDEX(_xlfn.ANCHORARRAY(Data!$M$65),8,2),0) -> 15 | L31: =IFERROR(VLOOKUP(J31,Data!$Q$8:$S$17,3,FALSE),0) -> 0
A32: =IFERROR(INDEX(_xlfn.ANCHORARRAY(Data!$P$65),5,1),"") -> Wax Papper Remover | B32: =IFERROR(INDEX(_xlfn.ANCHORARRAY(Data!$P$65),5,2),0) -> 5
A33: =IFERROR(INDEX(_xlfn.ANCHORARRAY(Data!$P$65),6,1),"") -> Cattle Pusher | B33: =IFERROR(INDEX(_xlfn.ANCHORARRAY(Data!$P$65),6,2),0) -> 5
A34: EXECUTIVE BRIEF | B34: =IFERROR(INDEX(_xlfn.ANCHORARRAY(Data!$P$65),7,2),0) -> 5
A35: =TEXT(Data!B2,"mmm dd")&": "&Data!B7&" YTD incidents ("&Data!B81&" "&TEXT(Data!B68,"+0%;-0%")&" vs prior). Rec "&Data!B8&" ("&TEXT(Data!B11,"0.0%")&")." -> Jul 27: 275 YTD incidents (▲ +95% vs prior). Rec 7 (2.5%). | B35: =Data!B14&" / "&Data!B13&" drive volume. "&Data!B17&" · Sev "&Data!B96&" ("&Data!B97&")." -> Fabrication / Strain drive volume. Medium Risk · Sev 43 (Elevated).
A36: PERFORMANCE VISUALS | B36: ="Live · "&TEXT(Data!B2,"mmm dd") -> Live · Jul 27
A101: WEEKLY TREND — ACTIVE FILTERS
A102: ="Dept: "&selDept&" · Area: "&selArea&" · Supervisor: "&selSup&" · Type: "&selType&" · ESI: "&selESI&" · Recordable: "&selRec&" · Year: "&selYear&" · Mode: "&selMode -> Dept: (All) · Area: (All) · Supervisor: (All) · Type: (All) · ESI: (All) · Recordable: (All) · Year: (All) · Mode: AND
A103: Change these on the 'Filter Dashboard' sheet — the weekly chart below updates automatically.

Sheet Data
A1: WORKPLACE SAFETY — DATA ENGINE | Z1: 2025
A2: Last refreshed | B2: =TODAY() -> 46230 | Z2: 2026
A3: Focus Year | B3: 2026
A4: Compare Year | B4: 2025
A6: Metric | B6: YTD 2026 | C6: FY 2025 | D6: YTD 2025 (Jan-Jul) | E6: Delta YTD | F6: Notes | H6: DEPARTMENT (2026 YTD) | N6: TOP INJURY / ILLNESS TYPES (2026) | Q6: TOP SUPERVISORS (2026)
A7: Total Incidents | B7: =COUNTIF(Master_List_Of_Injuries[Year],$B$3) -> 275 | C7: =COUNTIF(Master_List_Of_Injuries[Year],$B$4) -> 305 | D7: {=SUMPRODUCT((Master_List_Of_Injuries[Year]=$B$4)*(MONTH(Master_List_Of_Injuries[DOI])<=7)*1)} -> 141 | E7: =B7-D7 -> 134 | F7: All ESI statuses | H7: Department | I7: Incidents | J7: % of Total | K7: Recordables | N7: Injury Type | O7: Incidents | Q7: Supervisor | R7: Incidents | S7: Recordables
A8: Recordable Incidents | B8: {=SUMPRODUCT((Master_List_Of_Injuries[Year]=$B$3)*((Master_List_Of_Injuries[ESI Status]="RECORDABLE")+(Master_List_Of_Injuries[Recordable_Flag]="Yes")>0)*1)} -> 7 | C8: {=SUMPRODUCT((Master_List_Of_Injuries[Year]=$B$4)*((Master_List_Of_Injuries[ESI Status]="RECORDABLE")+(Master_List_Of_Injuries[Recordable_Flag]="Yes")>0)*1)} -> 10 | D8: {=SUMPRODUCT((Master_List_Of_Injuries[Year]=$B$4)*(MONTH(Master_List_Of_Injuries[DOI])<=7)*((Master_List_Of_Injuries[ESI Status]="RECORDABLE")+(Master_List_Of_Injuries[Recordable_Flag]="Yes")>0)*1)} -> 7 | E8: =B8-D8 -> 0 | F8: ESI=RECORDABLE or Flag=Yes | H8: Fabrication | I8: =COUNTIFS(Master_List_Of_Injuries[Year],$B$3,Master_List_Of_Injuries[[Department ]],H8) -> 132 | J8: =IFERROR(I8/$B$7,0) -> 0.48 | K8: {=SUMPRODUCT((Master_List_Of_Injuries[Year]=$B$3)*(Master_List_Of_Injuries[[Department ]]=H8)*((Master_List_Of_Injuries[ESI Status]="RECORDABLE")+(Master_List_Of_Injuries[Recordable_Flag]="Yes")>0)*1)} -> 2 | N8: Strain | O8: =COUNTIFS(Master_List_Of_Injuries[Year],$B$3,Master_List_Of_Injuries[Injury/Illness Type],N8) -> 97 | Q8: Samuel Sierra | R8: =COUNTIFS(Master_List_Of_Injuries[Year],$B$3,Master_List_Of_Injuries[Supervisor],Q8) -> 24 | S8: {=SUMPRODUCT((Master_List_Of_Injuries[Year]=$B$3)*(Master_List_Of_Injuries[Supervisor]=Q8)*((Master_List_Of_Injuries[ESI Status]="RECORDABLE")+(Master_List_Of_Injuries[Recordable_Flag]="Yes")>0)*1)} -> 1
A9: First Aid (FA) | B9: =COUNTIFS(Master_List_Of_Injuries[Year],$B$3,Master_List_Of_Injuries[ESI Status],"FA") -> 228 | C9: =COUNTIFS(Master_List_Of_Injuries[Year],$B$4,Master_List_Of_Injuries[ESI Status],"FA") -> 257 | D9: {=SUMPRODUCT((Master_List_Of_Injuries[Year]=$B$4)*(MONTH(Master_List_Of_Injuries[DOI])<=7)*(Master_List_Of_Injuries[ESI Status]="FA")*1)} -> 104 | E9: =B9-D9 -> 124 | H9: Harvest | I9: =COUNTIFS(Master_List_Of_Injuries[Year],$B$3,Master_List_Of_Injuries[[Department ]],H9) -> 106 | J9: =IFERROR(I9/$B$7,0) -> 0.38545455 | K9: {=SUMPRODUCT((Master_List_Of_Injuries[Year]=$B$3)*(Master_List_Of_Injuries[[Department ]]=H9)*((Master_List_Of_Injuries[ESI Status]="RECORDABLE")+(Master_List_Of_Injuries[Recordable_Flag]="Yes")>0)*1)} -> 3 | N9: Puncture | O9: =COUNTIFS(Master_List_Of_Injuries[Year],$B$3,Master_List_Of_Injuries[Injury/Illness Type],N9) -> 25 | Q9: Elizabeth Neufeld | R9: =COUNTIFS(Master_List_Of_Injuries[Year],$B$3,Master_List_Of_Injuries[Supervisor],Q9) -> 23 | S9: {=SUMPRODUCT((Master_List_Of_Injuries[Year]=$B$3)*(Master_List_Of_Injuries[Supervisor]=Q9)*((Master_List_Of_Injuries[ESI Status]="RECORDABLE")+(Master_List_Of_Injuries[Recordable_Flag]="Yes")>0)*1)} -> 0
A10: RPO / Modified Duty | B10: =COUNTIFS(Master_List_Of_Injuries[Year],$B$3,Master_List_Of_Injuries[ESI Status],"RPO") -> 40 | C10: =COUNTIFS(Master_List_Of_Injuries[Year],$B$4,Master_List_Of_Injuries[ESI Status],"RPO") -> 38 | D10: {=SUMPRODUCT((Master_List_Of_Injuries[Year]=$B$4)*(MONTH(Master_List_Of_Injuries[DOI])<=7)*(Master_List_Of_Injuries[ESI Status]="RPO")*1)} -> 30 | E10: =B10-D10 -> 10 | H10: Maintenance | I10: =COUNTIFS(Master_List_Of_Injuries[Year],$B$3,Master_List_Of_Injuries[[Department ]],H10) -> 10 | J10: =IFERROR(I10/$B$7,0) -> 0.036363636 | K10: {=SUMPRODUCT((Master_List_Of_Injuries[Year]=$B$3)*(Master_List_Of_Injuries[[Department ]]=H10)*((Master_List_Of_Injuries[ESI Status]="RECORDABLE")+(Master_List_Of_Injuries[Recordable_Flag]="Yes")>0)*1)} -> 0 | N10: Slip, Trip, & Fall | O10: =COUNTIFS(Master_List_Of_Injuries[Year],$B$3,Master_List_Of_Injuries[Injury/Illness Type],N10) -> 26 | Q10: Juan Ramirez | R10: =COUNTIFS(Master_List_Of_Injuries[Year],$B$3,Master_List_Of_Injuries[Supervisor],Q10) -> 21 | S10: {=SUMPRODUCT((Master_List_Of_Injuries[Year]=$B$3)*(Master_List_Of_Injuries[Supervisor]=Q10)*((Master_List_Of_Injuries[ESI Status]="RECORDABLE")+(Master_List_Of_Injuries[Recordable_Flag]="Yes")>0)*1)} -> 0
A11: Recordable % of Total | B11: =IFERROR(B8/B7,0) -> 0.025454545 | C11: =IFERROR(C8/C7,0) -> 0.032786885 | D11: =IFERROR(D8/D7,0) -> 0.04964539 | E11: =B11-D11 -> -0.024190845 | F11: Count-based rate | H11: Corrals | I11: =COUNTIFS(Master_List_Of_Injuries[Year],$B$3,Master_List_Of_Injuries[[Department ]],H11) -> 8 | J11: =IFERROR(I11/$B$7,0) -> 0.029090909 | K11: {=SUMPRODUCT((Master_List_Of_Injuries[Year]=$B$3)*(Master_List_Of_Injuries[[Department ]]=H11)*((Master_List_Of_Injuries[ESI Status]="RECORDABLE")+(Master_List_Of_Injuries[Recordable_Flag]="Yes")>0)*1)} -> 1 | N11: Rash | O11: =COUNTIFS(Master_List_Of_Injuries[Year],$B$3,Master_List_Of_Injuries[Injury/Illness Type],N11) -> 14 | Q11: Ovidio Sanchez | R11: =COUNTIFS(Master_List_Of_Injuries[Year],$B$3,Master_List_Of_Injuries[Supervisor],Q11) -> 21 | S11: {=SUMPRODUCT((Master_List_Of_Injuries[Year]=$B$3)*(Master_List_Of_Injuries[Supervisor]=Q11)*((Master_List_Of_Injuries[ESI Status]="RECORDABLE")+(Master_List_Of_Injuries[Recordable_Flag]="Yes")>0)*1)} -> 0
A12: Days Since Last Recordable | B12: =IFERROR(TODAY()-B16,0) -> 26 | F12: From TODAY() | H12: Warehouse | I12: =COUNTIFS(Master_List_Of_Injuries[Year],$B$3,Master_List_Of_Injuries[[Department ]],H12) -> 6 | J12: =IFERROR(I12/$B$7,0) -> 0.021818182 | K12: {=SUMPRODUCT((Master_List_Of_Injuries[Year]=$B$3)*(Master_List_Of_Injuries[[Department ]]=H12)*((Master_List_Of_Injuries[ESI Status]="RECORDABLE")+(Master_List_Of_Injuries[Recordable_Flag]="Yes")>0)*1)} -> 0 | N12: Foreign Object in Eye | O12: =COUNTIFS(Master_List_Of_Injuries[Year],$B$3,Master_List_Of_Injuries[Injury/Illness Type],N12) -> 0 | Q12: Alex Vargas | R12: =COUNTIFS(Master_List_Of_Injuries[Year],$B$3,Master_List_Of_Injuries[Supervisor],Q12) -> 19 | S12: {=SUMPRODUCT((Master_List_Of_Injuries[Year]=$B$3)*(Master_List_Of_Injuries[Supervisor]=Q12)*((Master_List_Of_Injuries[ESI Status]="RECORDABLE")+(Master_List_Of_Injuries[Recordable_Flag]="Yes")>0)*1)} -> 0
A13: Leading Injury Type | B13: =IFERROR(INDEX(_xlfn.ANCHORARRAY($G$65),1,1),"Strain") -> Strain | H13: Buildings & Grounds | I13: =COUNTIFS(Master_List_Of_Injuries[Year],$B$3,Master_List_Of_Injuries[[Department ]],H13) -> 4 | J13: =IFERROR(I13/$B$7,0) -> 0.014545455 | K13: {=SUMPRODUCT((Master_List_Of_Injuries[Year]=$B$3)*(Master_List_Of_Injuries[[Department ]]=H13)*((Master_List_Of_Injuries[ESI Status]="RECORDABLE")+(Master_List_Of_Injuries[Recordable_Flag]="Yes")>0)*1)} -> 0 | N13: Burn | O13: =COUNTIFS(Master_List_Of_Injuries[Year],$B$3,Master_List_Of_Injuries[Injury/Illness Type],N13) -> 12 | Q13: Diego Soria | R13: =COUNTIFS(Master_List_Of_Injuries[Year],$B$3,Master_List_Of_Injuries[Supervisor],Q13) -> 18 | S13: {=SUMPRODUCT((Master_List_Of_Injuries[Year]=$B$3)*(Master_List_Of_Injuries[Supervisor]=Q13)*((Master_List_Of_Injuries[ESI Status]="RECORDABLE")+(Master_List_Of_Injuries[Recordable_Flag]="Yes")>0)*1)} -> 2
A14: Top Department | B14: =IFERROR(INDEX(_xlfn.ANCHORARRAY($D$65),1,1),"Fabrication") -> Fabrication | H14: Outside Clean Up | I14: =COUNTIFS(Master_List_Of_Injuries[Year],$B$3,Master_List_Of_Injuries[[Department ]],H14) -> 3 | J14: =IFERROR(I14/$B$7,0) -> 0.010909091 | K14: {=SUMPRODUCT((Master_List_Of_Injuries[Year]=$B$3)*(Master_List_Of_Injuries[[Department ]]=H14)*((Master_List_Of_Injuries[ESI Status]="RECORDABLE")+(Master_List_Of_Injuries[Recordable_Flag]="Yes")>0)*1)} -> 1 | N14: Contact Stress | O14: =COUNTIFS(Master_List_Of_Injuries[Year],$B$3,Master_List_Of_Injuries[Injury/Illness Type],N14) -> 0 | Q14: Christian Lopez | R14: =COUNTIFS(Master_List_Of_Injuries[Year],$B$3,Master_List_Of_Injuries[Supervisor],Q14) -> 15 | S14: {=SUMPRODUCT((Master_List_Of_Injuries[Year]=$B$3)*(Master_List_Of_Injuries[Supervisor]=Q14)*((Master_List_Of_Injuries[ESI Status]="RECORDABLE")+(Master_List_Of_Injuries[Recordable_Flag]="Yes")>0)*1)} -> 0
A15: Latest Incident Date | B15: =_xlfn.MAXIFS(Master_List_Of_Injuries[DOI],Master_List_Of_Injuries[Year],$B$3) -> 46227 | H15: Loading Dock | I15: =COUNTIFS(Master_List_Of_Injuries[Year],$B$3,Master_List_Of_Injuries[[Department ]],H15) -> 3 | J15: =IFERROR(I15/$B$7,0) -> 0.010909091 | K15: {=SUMPRODUCT((Master_List_Of_Injuries[Year]=$B$3)*(Master_List_Of_Injuries[[Department ]]=H15)*((Master_List_Of_Injuries[ESI Status]="RECORDABLE")+(Master_List_Of_Injuries[Recordable_Flag]="Yes")>0)*1)} -> 0 | N15: Abrasion | O15: =COUNTIFS(Master_List_Of_Injuries[Year],$B$3,Master_List_Of_Injuries[Injury/Illness Type],N15) -> 9 | Q15: Chadu Moua | R15: =COUNTIFS(Master_List_Of_Injuries[Year],$B$3,Master_List_Of_Injuries[Supervisor],Q15) -> 15 | S15: {=SUMPRODUCT((Master_List_Of_Injuries[Year]=$B$3)*(Master_List_Of_Injuries[Supervisor]=Q15)*((Master_List_Of_Injuries[ESI Status]="RECORDABLE")+(Master_List_Of_Injuries[Recordable_Flag]="Yes")>0)*1)} -> 0
A16: Last Recordable Date | B16: =MAX(_xlfn.MAXIFS(Master_List_Of_Injuries[DOI],Master_List_Of_Injuries[Year],$B$3,Master_List_Of_Injuries[ESI Status],"RECORDABLE"),_xlfn.MAXIFS(Master_List_Of_Injuries[DOI],Master_List_Of_Injuries[Year],$B$3,Master_List_Of_Injuries[Recordable_Flag],"Yes")) -> 46204 | H16: FSQA | I16: =COUNTIFS(Master_List_Of_Injuries[Year],$B$3,Master_List_Of_Injuries[[Department ]],H16) -> 2 | J16: =IFERROR(I16/$B$7,0) -> 0.0072727273 | K16: {=SUMPRODUCT((Master_List_Of_Injuries[Year]=$B$3)*(Master_List_Of_Injuries[[Department ]]=H16)*((Master_List_Of_Injuries[ESI Status]="RECORDABLE")+(Master_List_Of_Injuries[Recordable_Flag]="Yes")>0)*1)} -> 0 | N16: Laceration | O16: =COUNTIFS(Master_List_Of_Injuries[Year],$B$3,Master_List_Of_Injuries[Injury/Illness Type],N16) -> 8 | Q16: Rutilo Rodriguez | R16: =COUNTIFS(Master_List_Of_Injuries[Year],$B$3,Master_List_Of_Injuries[Supervisor],Q16) -> 0 | S16: {=SUMPRODUCT((Master_List_Of_Injuries[Year]=$B$3)*(Master_List_Of_Injuries[Supervisor]=Q16)*((Master_List_Of_Injuries[ESI Status]="RECORDABLE")+(Master_List_Of_Injuries[Recordable_Flag]="Yes")>0)*1)} -> 0
A17: Safety Risk Status | B17: =IF(OR(B11>=0.05,B12<14),"High Risk",IF(OR(B11>=0.03,B12<30),"Medium Risk","Low Risk")) -> Medium Risk | F17: Based on recordable rate + recency | H17: Utilities | I17: =COUNTIFS(Master_List_Of_Injuries[Year],$B$3,Master_List_Of_Injuries[[Department ]],H17) -> 1 | J17: =IFERROR(I17/$B$7,0) -> 0.0036363636 | K17: {=SUMPRODUCT((Master_List_Of_Injuries[Year]=$B$3)*(Master_List_Of_Injuries[[Department ]]=H17)*((Master_List_Of_Injuries[ESI Status]="RECORDABLE")+(Master_List_Of_Injuries[Recordable_Flag]="Yes")>0)*1)} -> 0 | N17: Struck By Cattle | O17: =COUNTIFS(Master_List_Of_Injuries[Year],$B$3,Master_List_Of_Injuries[Injury/Illness Type],N17) -> 7 | Q17: Richard Xiong | R17: =COUNTIFS(Master_List_Of_Injuries[Year],$B$3,Master_List_Of_Injuries[Supervisor],Q17) -> 15 | S17: {=SUMPRODUCT((Master_List_Of_Injuries[Year]=$B$3)*(Master_List_Of_Injuries[Supervisor]=Q17)*((Master_List_Of_Injuries[ESI Status]="RECORDABLE")+(Master_List_Of_Injuries[Recordable_Flag]="Yes")>0)*1)} -> 0
H18: Recycling | I18: =COUNTIFS(Master_List_Of_Injuries[Year],$B$3,Master_List_Of_Injuries[[Department ]],H18) -> 0 | J18: =IFERROR(I18/$B$7,0) -> 0 | K18: {=SUMPRODUCT((Master_List_Of_Injuries[Year]=$B$3)*(Master_List_Of_Injuries[[Department ]]=H18)*((Master_List_Of_Injuries[ESI Status]="RECORDABLE")+(Master_List_Of_Injuries[Recordable_Flag]="Yes")>0)*1)} -> 0 | N18: Inhalation / Reaction | O18: =COUNTIFS(Master_List_Of_Injuries[Year],$B$3,Master_List_Of_Injuries[Injury/Illness Type],N18) -> 7
N19: Crush Injury | O19: =COUNTIFS(Master_List_Of_Injuries[Year],$B$3,Master_List_Of_Injuries[Injury/Illness Type],N19) -> 1
A20: MONTHLY INCIDENT TREND | N20: Struck By/Against Object | O20: =COUNTIFS(Master_List_Of_Injuries[Year],$B$3,Master_List_Of_Injuries[Injury/Illness Type],N20) -> 0 | Q20: TOP JTPs / JOBS (2026)
A21: Month | B21: # | C21: 2025 Incidents | D21: 2026 Incidents | E21: 2025 Recordable | F21: 2026 Recordable | H21: ESI STATUS (2026 YTD) | N21: Struck By Equipment | O21: =COUNTIFS(Master_List_Of_Injuries[Year],$B$3,Master_List_Of_Injuries[Injury/Illness Type],N21) -> 3 | Q21: JTP | R21: Incidents
A22: January | B22: 1 | C22: =COUNTIFS(Master_List_Of_Injuries[Year],$B$4,Master_List_Of_Injuries[Month.1],A22) -> 23 | D22: =COUNTIFS(Master_List_Of_Injuries[Year],$B$3,Master_List_Of_Injuries[Month.1],A22) -> 28 | E22: {=SUMPRODUCT((Master_List_Of_Injuries[Year]=$B$4)*(Master_List_Of_Injuries[Month.1]=A22)*((Master_List_Of_Injuries[ESI Status]="RECORDABLE")+(Master_List_Of_Injuries[Recordable_Flag]="Yes")>0)*1)} -> 1 | F22: {=SUMPRODUCT((Master_List_Of_Injuries[Year]=$B$3)*(Master_List_Of_Injuries[Month.1]=A22)*((Master_List_Of_Injuries[ESI Status]="RECORDABLE")+(Master_List_Of_Injuries[Recordable_Flag]="Yes")>0)*1)} -> 1 | H22: ESI Status | I22: Incidents | J22: % | Q22: Whizzard Knife Op. | R22: =COUNTIFS(Master_List_Of_Injuries[Year],$B$3,Master_List_Of_Injuries[JTP:],Q22) -> 5
A23: February | B23: 2 | C23: =COUNTIFS(Master_List_Of_Injuries[Year],$B$4,Master_List_Of_Injuries[Month.1],A23) -> 19 | D23: =COUNTIFS(Master_List_Of_Injuries[Year],$B$3,Master_List_Of_Injuries[Month.1],A23) -> 44 | E23: {=SUMPRODUCT((Master_List_Of_Injuries[Year]=$B$4)*(Master_List_Of_Injuries[Month.1]=A23)*((Master_List_Of_Injuries[ESI Status]="RECORDABLE")+(Master_List_Of_Injuries[Recordable_Flag]="Yes")>0)*1)} -> 3 | F23: {=SUMPRODUCT((Master_List_Of_Injuries[Year]=$B$3)*(Master_List_Of_Injuries[Month.1]=A23)*((Master_List_Of_Injuries[ESI Status]="RECORDABLE")+(Master_List_Of_Injuries[Recordable_Flag]="Yes")>0)*1)} -> 0 | H23: FA | I23: =COUNTIFS(Master_List_Of_Injuries[Year],$B$3,Master_List_Of_Injuries[ESI Status],H23) -> 228 | J23: =IFERROR(I23/$B$7,0) -> 0.82909091 | Q23: Tender Puller | R23: =COUNTIFS(Master_List_Of_Injuries[Year],$B$3,Master_List_Of_Injuries[JTP:],Q23) -> 8
A24: March | B24: 3 | C24: =COUNTIFS(Master_List_Of_Injuries[Year],$B$4,Master_List_Of_Injuries[Month.1],A24) -> 24 | D24: =COUNTIFS(Master_List_Of_Injuries[Year],$B$3,Master_List_Of_Injuries[Month.1],A24) -> 31 | E24: {=SUMPRODUCT((Master_List_Of_Injuries[Year]=$B$4)*(Master_List_Of_Injuries[Month.1]=A24)*((Master_List_Of_Injuries[ESI Status]="RECORDABLE")+(Master_List_Of_Injuries[Recordable_Flag]="Yes")>0)*1)} -> 1 | F24: {=SUMPRODUCT((Master_List_Of_Injuries[Year]=$B$3)*(Master_List_Of_Injuries[Month.1]=A24)*((Master_List_Of_Injuries[ESI Status]="RECORDABLE")+(Master_List_Of_Injuries[Recordable_Flag]="Yes")>0)*1)} -> 1 | H24: RPO | I24: =COUNTIFS(Master_List_Of_Injuries[Year],$B$3,Master_List_Of_Injuries[ESI Status],H24) -> 40 | J24: =IFERROR(I24/$B$7,0) -> 0.14545455 | N24: TOP AREAS (2026) | Q24: Plate Boner | R24: =COUNTIFS(Master_List_Of_Injuries[Year],$B$3,Master_List_Of_Injuries[JTP:],Q24) -> 6
A25: April | B25: 4 | C25: =COUNTIFS(Master_List_Of_Injuries[Year],$B$4,Master_List_Of_Injuries[Month.1],A25) -> 17 | D25: =COUNTIFS(Master_List_Of_Injuries[Year],$B$3,Master_List_Of_Injuries[Month.1],A25) -> 48 | E25: {=SUMPRODUCT((Master_List_Of_Injuries[Year]=$B$4)*(Master_List_Of_Injuries[Month.1]=A25)*((Master_List_Of_Injuries[ESI Status]="RECORDABLE")+(Master_List_Of_Injuries[Recordable_Flag]="Yes")>0)*1)} -> 0 | F25: {=SUMPRODUCT((Master_List_Of_Injuries[Year]=$B$3)*(Master_List_Of_Injuries[Month.1]=A25)*((Master_List_Of_Injuries[ESI Status]="RECORDABLE")+(Master_List_Of_Injuries[Recordable_Flag]="Yes")>0)*1)} -> 1 | H25: RECORDABLE | I25: =COUNTIFS(Master_List_Of_Injuries[Year],$B$3,Master_List_Of_Injuries[ESI Status],H25) -> 7 | J25: =IFERROR(I25/$B$7,0) -> 0.025454545 | N25: Area | O25: Incidents | Q25: Intestine Stripper | R25: =COUNTIFS(Master_List_Of_Injuries[Year],$B$3,Master_List_Of_Injuries[JTP:],Q25) -> 6
A26: May | B26: 5 | C26: =COUNTIFS(Master_List_Of_Injuries[Year],$B$4,Master_List_Of_Injuries[Month.1],A26) -> 22 | D26: =COUNTIFS(Master_List_Of_Injuries[Year],$B$3,Master_List_Of_Injuries[Month.1],A26) -> 25 | E26: {=SUMPRODUCT((Master_List_Of_Injuries[Year]=$B$4)*(Master_List_Of_Injuries[Month.1]=A26)*((Master_List_Of_Injuries[ESI Status]="RECORDABLE")+(Master_List_Of_Injuries[Recordable_Flag]="Yes")>0)*1)} -> 0 | F26: {=SUMPRODUCT((Master_List_Of_Injuries[Year]=$B$3)*(Master_List_Of_Injuries[Month.1]=A26)*((Master_List_Of_Injuries[ESI Status]="RECORDABLE")+(Master_List_Of_Injuries[Recordable_Flag]="Yes")>0)*1)} -> 1 | N26: 102 | O26: =COUNTIFS(Master_List_Of_Injuries[Year],$B$3,Master_List_Of_Injuries[Area],N26) -> 32 | Q26: Wax Papper Remover | R26: =COUNTIFS(Master_List_Of_Injuries[Year],$B$3,Master_List_Of_Injuries[JTP:],Q26) -> 5
A27: June | B27: 6 | C27: =COUNTIFS(Master_List_Of_Injuries[Year],$B$4,Master_List_Of_Injuries[Month.1],A27) -> 21 | D27: =COUNTIFS(Master_List_Of_Injuries[Year],$B$3,Master_List_Of_Injuries[Month.1],A27) -> 56 | E27: {=SUMPRODUCT((Master_List_Of_Injuries[Year]=$B$4)*(Master_List_Of_Injuries[Month.1]=A27)*((Master_List_Of_Injuries[ESI Status]="RECORDABLE")+(Master_List_Of_Injuries[Recordable_Flag]="Yes")>0)*1)} -> 1 | F27: {=SUMPRODUCT((Master_List_Of_Injuries[Year]=$B$3)*(Master_List_Of_Injuries[Month.1]=A27)*((Master_List_Of_Injuries[ESI Status]="RECORDABLE")+(Master_List_Of_Injuries[Recordable_Flag]="Yes")>0)*1)} -> 2 | N27: 410 | O27: =COUNTIFS(Master_List_Of_Injuries[Year],$B$3,Master_List_Of_Injuries[Area],N27) -> 23 | Q27: Cattle Pusher | R27: =COUNTIFS(Master_List_Of_Injuries[Year],$B$3,Master_List_Of_Injuries[JTP:],Q27) -> 5
A28: July | B28: 7 | C28: =COUNTIFS(Master_List_Of_Injuries[Year],$B$4,Master_List_Of_Injuries[Month.1],A28) -> 15 | D28: =COUNTIFS(Master_List_Of_Injuries[Year],$B$3,Master_List_Of_Injuries[Month.1],A28) -> 43 | E28: {=SUMPRODUCT((Master_List_Of_Injuries[Year]=$B$4)*(Master_List_Of_Injuries[Month.1]=A28)*((Master_List_Of_Injuries[ESI Status]="RECORDABLE")+(Master_List_Of_Injuries[Recordable_Flag]="Yes")>0)*1)} -> 1 | F28: {=SUMPRODUCT((Master_List_Of_Injuries[Year]=$B$3)*(Master_List_Of_Injuries[Month.1]=A28)*((Master_List_Of_Injuries[ESI Status]="RECORDABLE")+(Master_List_Of_Injuries[Recordable_Flag]="Yes")>0)*1)} -> 1 | N28: 420 | O28: =COUNTIFS(Master_List_Of_Injuries[Year],$B$3,Master_List_Of_Injuries[Area],N28) -> 22 | Q28: Herdsman | R28: =COUNTIFS(Master_List_Of_Injuries[Year],$B$3,Master_List_Of_Injuries[JTP:],Q28) -> 5
A29: August | B29: 8 | C29: =COUNTIFS(Master_List_Of_Injuries[Year],$B$4,Master_List_Of_Injuries[Month.1],A29) -> 20 | D29: =COUNTIFS(Master_List_Of_Injuries[Year],$B$3,Master_List_Of_Injuries[Month.1],A29) -> 0 | E29: {=SUMPRODUCT((Master_List_Of_Injuries[Year]=$B$4)*(Master_List_Of_Injuries[Month.1]=A29)*((Master_List_Of_Injuries[ESI Status]="RECORDABLE")+(Master_List_Of_Injuries[Recordable_Flag]="Yes")>0)*1)} -> 2 | F29: {=SUMPRODUCT((Master_List_Of_Injuries[Year]=$B$3)*(Master_List_Of_Injuries[Month.1]=A29)*((Master_List_Of_Injuries[ESI Status]="RECORDABLE")+(Master_List_Of_Injuries[Recordable_Flag]="Yes")>0)*1)} -> 0 | N29: 400 | O29: =COUNTIFS(Master_List_Of_Injuries[Year],$B$3,Master_List_Of_Injuries[Area],N29) -> 21 | Q29: Chuck Boner | R29: =COUNTIFS(Master_List_Of_Injuries[Year],$B$3,Master_List_Of_Injuries[JTP:],Q29) -> 0
A30: September | B30: 9 | C30: =COUNTIFS(Master_List_Of_Injuries[Year],$B$4,Master_List_Of_Injuries[Month.1],A30) -> 34 | D30: =COUNTIFS(Master_List_Of_Injuries[Year],$B$3,Master_List_Of_Injuries[Month.1],A30) -> 0 | E30: {=SUMPRODUCT((Master_List_Of_Injuries[Year]=$B$4)*(Master_List_Of_Injuries[Month.1]=A30)*((Master_List_Of_Injuries[ESI Status]="RECORDABLE")+(Master_List_Of_Injuries[Recordable_Flag]="Yes")>0)*1)} -> 0 | F30: {=SUMPRODUCT((Master_List_Of_Injuries[Year]=$B$3)*(Master_List_Of_Injuries[Month.1]=A30)*((Master_List_Of_Injuries[ESI Status]="RECORDABLE")+(Master_List_Of_Injuries[Recordable_Flag]="Yes")>0)*1)} -> 0 | N30: 405 | O30: =COUNTIFS(Master_List_Of_Injuries[Year],$B$3,Master_List_Of_Injuries[Area],N30) -> 20 | Q30: Maintenance | R30: =COUNTIFS(Master_List_Of_Injuries[Year],$B$3,Master_List_Of_Injuries[JTP:],Q30) -> 1
A31: October | B31: 10 | C31: =COUNTIFS(Master_List_Of_Injuries[Year],$B$4,Master_List_Of_Injuries[Month.1],A31) -> 42 | D31: =COUNTIFS(Master_List_Of_Injuries[Year],$B$3,Master_List_Of_Injuries[Month.1],A31) -> 0 | E31: {=SUMPRODUCT((Master_List_Of_Injuries[Year]=$B$4)*(Master_List_Of_Injuries[Month.1]=A31)*((Master_List_Of_Injuries[ESI Status]="RECORDABLE")+(Master_List_Of_Injuries[Recordable_Flag]="Yes")>0)*1)} -> 0 | F31: {=SUMPRODUCT((Master_List_Of_Injuries[Year]=$B$3)*(Master_List_Of_Injuries[Month.1]=A31)*((Master_List_Of_Injuries[ESI Status]="RECORDABLE")+(Master_List_Of_Injuries[Recordable_Flag]="Yes")>0)*1)} -> 0 | N31: 109 | O31: =COUNTIFS(Master_List_Of_Injuries[Year],$B$3,Master_List_Of_Injuries[Area],N31) -> 16 | Q31: Trimmer | R31: =COUNTIFS(Master_List_Of_Injuries[Year],$B$3,Master_List_Of_Injuries[JTP:],Q31) -> 1
A32: November | B32: 11 | C32: =COUNTIFS(Master_List_Of_Injuries[Year],$B$4,Master_List_Of_Injuries[Month.1],A32) -> 37 | D32: =COUNTIFS(Master_List_Of_Injuries[Year],$B$3,Master_List_Of_Injuries[Month.1],A32) -> 0 | E32: {=SUMPRODUCT((Master_List_Of_Injuries[Year]=$B$4)*(Master_List_Of_Injuries[Month.1]=A32)*((Master_List_Of_Injuries[ESI Status]="RECORDABLE")+(Master_List_Of_Injuries[Recordable_Flag]="Yes")>0)*1)} -> 0 | F32: {=SUMPRODUCT((Master_List_Of_Injuries[Year]=$B$3)*(Master_List_Of_Injuries[Month.1]=A32)*((Master_List_Of_Injuries[ESI Status]="RECORDABLE")+(Master_List_Of_Injuries[Recordable_Flag]="Yes")>0)*1)} -> 0 | N32: 429 | O32: =COUNTIFS(Master_List_Of_Injuries[Year],$B$3,Master_List_Of_Injuries[Area],N32) -> 15
A33: December | B33: 12 | C33: =COUNTIFS(Master_List_Of_Injuries[Year],$B$4,Master_List_Of_Injuries[Month.1],A33) -> 31 | D33: =COUNTIFS(Master_List_Of_Injuries[Year],$B$3,Master_List_Of_Injuries[Month.1],A33) -> 0 | E33: {=SUMPRODUCT((Master_List_Of_Injuries[Year]=$B$4)*(Master_List_Of_Injuries[Month.1]=A33)*((Master_List_Of_Injuries[ESI Status]="RECORDABLE")+(Master_List_Of_Injuries[Recordable_Flag]="Yes")>0)*1)} -> 1 | F33: {=SUMPRODUCT((Master_List_Of_Injuries[Year]=$B$3)*(Master_List_Of_Injuries[Month.1]=A33)*((Master_List_Of_Injuries[ESI Status]="RECORDABLE")+(Master_List_Of_Injuries[Recordable_Flag]="Yes")>0)*1)} -> 0 | N33: 101 | O33: =COUNTIFS(Master_List_Of_Injuries[Year],$B$3,Master_List_Of_Injuries[Area],N33) -> 16
N34: 106 | O34: =COUNTIFS(Master_List_Of_Injuries[Year],$B$3,Master_List_Of_Injuries[Area],N34) -> 14
N35: 100 | O35: =COUNTIFS(Master_List_Of_Injuries[Year],$B$3,Master_List_Of_Injuries[Area],N35) -> 12
A36: Month | B36: 2025 | C36: 2026 | N36: 415 | O36: =COUNTIFS(Master_List_Of_Injuries[Year],$B$3,Master_List_Of_Injuries[Area],N36) -> 11
A37: Jan | B37: =C22 -> 23 | C37: =D22 -> 28 | N37: 447 | O37: =COUNTIFS(Master_List_Of_Injuries[Year],$B$3,Master_List_Of_Injuries[Area],N37) -> 4
A38: Feb | B38: =C23 -> 19 | C38: =D23 -> 44
A39: Mar | B39: =C24 -> 24 | C39: =D24 -> 31
A40: Apr | B40: =C25 -> 17 | C40: =D25 -> 48
A41: May | B41: =C26 -> 22 | C41: =D26 -> 25
...

Sheet PivotCache
A1: Pivot cache
A3: Row Labels | B3: Incidents | D3: Row Labels | E3: Incidents | G3: Row Labels | H3: Incidents | J3: Row Labels | K3: Incidents
A4: FA | B4: 485 | D4: Corrals | E4: 2 | G4: 2025 | H4: 305 | J4: Above Shoulder Work | K4: 1
A5: RECORDABLE | B5: 17 | D5: Fabrication | E5: 50 | G5: Grand Total | H5: 305 | J5: Abrasion | K5: 9
A6: RPO | B6: 78 | D6: FSQA | E6: 1 | J6: Abrasion | K6: 12
A7: Grand Total | B7: 580 | D7: Harvest | E7: 50 | J7: Awkward Posture | K7: 1
D8: Loading Dock | E8: 1 | J8: Bending | K8: 2
D9: Maintenance | E9: 3 | J9: Box Maker | K9: 2
D10: Outside Clean Up | E10: 2 | J10: Burn | K10: 17
D11: Warehouse | E11: 5 | J11: Burn | K11: 12
D12: Grand Total | E12: 114 | J12: Contact Stess | K12: 10
J13: Contact Stress | K13: 7
J14: Contusion | K14: 1
J15: Contusions | K15: 6
J16: Crush | K16: 1
J17: Crush Injury | K17: 4
J18: Crush Injury | K18: 7
J19: Electric Shock | K19: 3
J20: Falling Object | K20: 5
J21: Falling Objects | K21: 1
J22: Foreign boby in eye | K22: 19
J23: Foreign Object | K23: 18
J24: Heat Prostration | K24: 1
... J66: Grand Total | K66: 580

Sheet Notes
A1: WORKPLACE SAFETY DASHBOARD — GUIDE
A3: SHEET MAP
A4: Dashboard — Executive KPIs, findings, charts, slicers
A5: Data — Engine + year dropdowns (B3 focus, B4 compare)
A6: Master_List_Of_Injuries — Source table (append rows here)
A7: PivotCache — Pivots for slicers
A8: Notes — This guide
A10: HOW TO UPDATE
A11: 1. Add incidents to the master list table.
A12: 2. Set Data!B3 (focus year) and Data!B4 (compare year).
A13: 3. Dashboard refreshes automatically.
A14: 4. Slicers filter PivotCache only; KPIs stay full YTD.
... A23: Rate = recordables / total incidents (count-based)

Sheet Month
B3: Count of DOI
A4: February | B4: 63
A5: April | B5: 65
A6: May | B6: 47
A7: June | B7: 77
A8: Grand Total | B8: 252

Sheet FA-RPO-RECORDABLE
A3: Count of DOI | B3: Column Labels
A4: Row Labels | B4: RECORDABLE | C4: Grand Total
A5: 2025 | B5: 4 | C5: 4
A6: February | B6: 3 | C6: 3
A7: June | B7: 1 | C7: 1
A8: 2026 | B8: 4 | C8: 4
A9: April | B9: 1 | C9: 1
A10: May | B10: 1 | C10: 1
A11: June | B11: 2 | C11: 2
A12: Grand Total | B12: 8 | C12: 8

Sheet YEAR
A3: Row Labels | B3: Count of DOI
A4: 2025 | B4: 79
A5: 2026 | B5: 173
A6: Grand Total | B6: 252

Sheet BY QTRS
A3: Count of DOI
A4: 580

Sheet BY DEPARTMENT
A3: Row Labels | B3: Count of DOI
A4: Corrals | B4: 1
A5: 2026 | B5: 1
A6: Fabrication | B6: 4
A7: 2025 | B7: 2
A8: 2026 | B8: 2
A9: Harvest | B9: 10
A10: 2025 | B10: 7
A11: 2026 | B11: 3
A12: Maintnances | B12: 1
A13: 2025 | B13: 1
A14: Outside Clean Up | B14: 1
A15: 2026 | B15: 1
A16: Grand Total | B16: 17

Sheet ERGO
A3: Row Labels | B3: Count of Body Location
A4: 2026 | B4: 275
A5: January | B5: 28
A6: Abrasion | B6: 1
A7: Burn | B7: 1
A8: Laceration | B8: 2
A9: Pinch-Point | B9: 1
A10: Puncture | B10: 2
A11: Rash | B11: 2
A12: Slip, Trip, & Fall | B12: 2
A13: Sprain | B13: 1
A14: Strain | B14: 14
A15: Foreign Object | B15: 2
A16: February | B16: 44
... A108: Grand Total | B108: 275

Sheet Area
A1: Month.1 | B1: May
A2: Year | B2: 2026
A4: Row Labels | B4: Count of DOI
A5: FSQA | B5: 1
A6: Utilities | B6: 1
A7: Grand Total | B7: 2

Sheet ERgo By Dept
A5: Row Labels | B5: Count of Body Location | C5: Count of Injury/Illness Type
A6: Fabrication | B6: 6 | C6: 6
A7: 46076 | B7: 2 | C7: 2
A8: 46078 | B8: 1 | C8: 1
A9: 46080 | B9: 3 | C9: 3
A10: Harvest | B10: 5 | C10: 5
A11: 46077 | B11: 1 | C11: 1
A12: 46078 | B12: 2 | C12: 2
A13: 46079 | B13: 2 | C13: 2
A14: Warehouse | B14: 5 | C14: 5
A15: 46076 | B15: 5 | C15: 5
A16: Grand Total | B16: 16 | C16: 16

Sheet FA
A3: Count of DOI
B4: FA | C4: RPO | D4: Grand Total
A5: 46210 | B5: 2 | C5: 1 | D5: 3
A6: 46211 | B6: 2 | C6: 3 | D6: 5
A7: 46212 | B7: 4 | C7: 1 | D7: 5
A8: 46213 | B8: 2 | C8: 1 | D8: 3
A9: Grand Total | B9: 10 | C9: 6 | D9: 16

Sheet Dashboard Data
A1: Metric | B1: Value | D1: Month | E1: Incidents | F1: Recordable | H1: Department | I1: Incidents | K1: ESI Status | L1: Incidents | N1: Injury/Illness Type | O1: Incidents | Q1: Area | R1: Incidents
A2: Total current-year incidents | B2: =COUNTIF(Master_List_Of_Injuries[Year],2026) -> 275 | D2: January | E2: =COUNTIFS(Master_List_Of_Injuries[Year],2026,Master_List_Of_Injuries[Month.1],D2) -> 28 | F2: {=SUMPRODUCT((Master_List_Of_Injuries[Year]=2026)*(Master_List_Of_Injuries[Month.1]=D2)*(((Master_List_Of_Injuries[ESI Status]="RECORDABLE")+(Master_List_Of_Injuries[Recordable_Flag]="Yes"))>0))} -> 1 | H2: Fabrication | I2: =IF(H2="","",COUNTIFS(Master_List_Of_Injuries[Year],2026,Master_List_Of_Injuries[[Department ]],H2)) -> 132 | K2: FA | L2: =IF(K2="","",COUNTIFS(Master_List_Of_Injuries[Year],2026,Master_List_Of_Injuries[ESI Status],K2)) -> 228 | N2: Strain | O2: {=IF(N2="","",SUMPRODUCT((Master_List_Of_Injuries[Year]=2026)*(TRIM(Master_List_Of_Injuries[Injury/Illness Type])=N2)))} -> 99 | Q2: 102 | R2: =IF(Q2="","",COUNTIFS(Master_List_Of_Injuries[Year],2026,Master_List_Of_Injuries[Area],Q2)) -> 32
A3: Recordable incidents | B3: {=SUMPRODUCT((Master_List_Of_Injuries[Year]=2026)*(((Master_List_Of_Injuries[ESI Status]="RECORDABLE")+(Master_List_Of_Injuries[Recordable_Flag]="Yes"))>0))} -> 7 | D3: February | E3: =COUNTIFS(Master_List_Of_Injuries[Year],2026,Master_List_Of_Injuries[Month.1],D3) -> 44 | F3: {=SUMPRODUCT((Master_List_Of_Injuries[Year]=2026)*(Master_List_Of_Injuries[Month.1]=D3)*(((Master_List_Of_Injuries[ESI Status]="RECORDABLE")+(Master_List_Of_Injuries[Recordable_Flag]="Yes"))>0))} -> 0 | H3: Harvest | I3: =IF(H3="","",COUNTIFS(Master_List_Of_Injuries[Year],2026,Master_List_Of_Injuries[[Department ]],H3)) -> 106 | K3: RPO | L3: =IF(K3="","",COUNTIFS(Master_List_Of_Injuries[Year],2026,Master_List_Of_Injuries[ESI Status],K3)) -> 40 | N3: Puncture | O3: {=IF(N3="","",SUMPRODUCT((Master_List_Of_Injuries[Year]=2026)*(TRIM(Master_List_Of_Injuries[Injury/Illness Type])=N3)))} -> 25 | Q3: 410 | R3: =IF(Q3="","",COUNTIFS(Master_List_Of_Injuries[Year],2026,Master_List_Of_Injuries[Area],Q3)) -> 23
A4: FA incidents | B4: =COUNTIFS(Master_List_Of_Injuries[Year],2026,Master_List_Of_Injuries[ESI Status],"FA") -> 228 | D4: March | E4: =COUNTIFS(Master_List_Of_Injuries[Year],2026,Master_List_Of_Injuries[Month.1],D4) -> 31 | F4: {=SUMPRODUCT((Master_List_Of_Injuries[Year]=2026)*(Master_List_Of_Injuries[Month.1]=D4)*(((Master_List_Of_Injuries[ESI Status]="RECORDABLE")+(Master_List_Of_Injuries[Recordable_Flag]="Yes"))>0))} -> 1 | H4: Maintenance | I4: =IF(H4="","",COUNTIFS(Master_List_Of_Injuries[Year],2026,Master_List_Of_Injuries[[Department ]],H4)) -> 10 | K4: RECORDABLE | L4: =IF(K4="","",COUNTIFS(Master_List_Of_Injuries[Year],2026,Master_List_Of_Injuries[ESI Status],K4)) -> 7 | N4: Slip, Trip, & Fall | O4: {=IF(N4="","",SUMPRODUCT((Master_List_Of_Injuries[Year]=2026)*(TRIM(Master_List_Of_Injuries[Injury/Illness Type])=N4)))} -> 26 | Q4: 420 | R4: =IF(Q4="","",COUNTIFS(Master_List_Of_Injuries[Year],2026,Master_List_Of_Injuries[Area],Q4)) -> 22
A5: RPO incidents | B5: =COUNTIFS(Master_List_Of_Injuries[Year],2026,Master_List_Of_Injuries[ESI Status],"RPO") -> 40 | D5: April | E5: =COUNTIFS(Master_List_Of_Injuries[Year],2026,Master_List_Of_Injuries[Month.1],D5) -> 48 | F5: {=SUMPRODUCT((Master_List_Of_Injuries[Year]=2026)*(Master_List_Of_Injuries[Month.1]=D5)*(((Master_List_Of_Injuries[ESI Status]="RECORDABLE")+(Master_List_Of_Injuries[Recordable_Flag]="Yes"))>0))} -> 1 | H5: Corrals | I5: =IF(H5="","",COUNTIFS(Master_List_Of_Injuries[Year],2026,Master_List_Of_Injuries[[Department ]],H5)) -> 8 | L5: =IF(K5="","",COUNTIFS(Master_List_Of_Injuries[Year],2026,Master_List_Of_Injuries[ESI Status],K5)) | N5: Rash | O5: {=IF(N5="","",SUMPRODUCT((Master_List_Of_Injuries[Year]=2026)*(TRIM(Master_List_Of_Injuries[Injury/Illness Type])=N5)))} -> 14 | Q5: 400 | R5: =IF(Q5="","",COUNTIFS(Master_List_Of_Injuries[Year],2026,Master_List_Of_Injuries[Area],Q5)) -> 21
A6: Latest month incidents | B6: {=INDEX(E2:E13,MATCH(2,1/(E2:E13<>"")))} -> 43 | D6: May | E6: =COUNTIFS(Master_List_Of_Injuries[Year],2026,Master_List_Of_Injuries[Month.1],D6) -> 25 | F6: {=SUMPRODUCT((Master_List_Of_Injuries[Year]=2026)*(Master_List_Of_Injuries[Month.1]=D6)*(((Master_List_Of_Injuries[ESI Status]="RECORDABLE")+(Master_List_Of_Injuries[Recordable_Flag]="Yes"))>0))} -> 1 | H6: Warehouse | I6: =IF(H6="","",COUNTIFS(Master_List_Of_Injuries[Year],2026,Master_List_Of_Injuries[[Department ]],H6)) -> 6 | L6: =IF(K6="","",COUNTIFS(Master_List_Of_Injuries[Year],2026,Master_List_Of_Injuries[ESI Status],K6)) | N6: Foreign Object in Eye | O6: {=IF(N6="","",SUMPRODUCT((Master_List_Of_Injuries[Year]=2026)*(TRIM(Master_List_Of_Injuries[Injury/Illness Type])=N6)))} -> 0 | Q6: 405 | R6: =IF(Q6="","",COUNTIFS(Master_List_Of_Injuries[Year],2026,Master_List_Of_Injuries[Area],Q6)) -> 20
